<?xml version="1.0" ?>
<!-- base link coordinate system -->
<robot name="Jason_Robot">
    <link name="base_link">
        <visual>
            <origin xyz="0 0 0" rpy="0 0 0" />
            <geometry>
                <cylinder length="0.005" radius="0.13" />
            </geometry>
            <material name="orange">
                <color rgba="1 0.7 0 1" />
            </material>
        </visual>
    </link>

    <!-- left motor and joint -->
    <joint name="base_left_motor_joint" type="fixed">
        <origin xyz="-0.055 0.075 0" rpy="0 0 0" />
        <parent link="base_link" />
        <child link="left_motor" />
    </joint>

    <link name="left_motor">
        <visual>
            <origin xyz="0 0 0" rpy="1.5707 0 0" />
            <geometry>
                <cylinder radius="0.02" length="0.08"/>
            </geometry>
            <material name="gray">
                <color rgba="0.8 0.8 0.8 1"/>
            </material>
        </visual>
    </link>

    <!-- left wheel and joint -->
    <joint name="left_wheel_joint" type="continuous">
        <origin xyz="0 0.0485 0" rpy="0 0 0" />
        <parent link="left_motor"/>
        <child link="left_wheel_link"/>
        <axis xyz="0 1 0"/>
    </joint>

    <link name="left_wheel_link">
        <visual>
            <origin xyz="0 0 0" rpy="1.5707 0 0" />
            <geometry>
                <cylinder length="0.017" radius="0.033"/>
            </geometry>
            <material name="white">
                <color rgba="1 1 1 0.9"/>
            </material>
        </visual>
    </link>

    <!-- right motor and joint -->
    <joint name="base_right_motor_joint" type="fixed">
        <origin xyz="-0.055 -0.075 0" rpy="0 0 0" />
        <parent link="base_link" />
        <child link="right_motor" />
    </joint>

    <link name="right_motor">
        <visual>
            <origin xyz="0 0 0" rpy="1.5707 0 0" />
            <geometry>
                <cylinder length="0.08" radius="0.02" />
            </geometry>
            <material name="gray">
                <color rgba="0.8 0.8 0.8 1" />
            </material>
        </visual>
    </link>

    <!-- right wheel and joint -->
        <joint name="right_wheel_joint" type="continuous">
        <origin xyz="0 -0.0485 0" rpy="0 0 0" />
        <parent link="right_motor"/>
        <child link="right_wheel_link"/>
        <axis xyz="0 1 0"/>
    </joint>

    <link name="right_wheel_link">
        <visual>
            <origin xyz="0 0 0" rpy="1.5707 0 0" />
            <geometry>
                <cylinder length="0.017" radius="0.033"/>
            </geometry>
            <material name="white">
                <color rgba="1 1 1 0.9"/>
            </material>
        </visual>
    </link>

    <!-- front castor and joint-->
    <!-- For joint type, we can use "continuous" to recognize this joint.
    By "fixed" type this joint can't be recognized. -->
    <joint name="front_castor_joint" type="continuous">
        <origin xyz="0.1135 0 -0.0165" rpy="0 0 0" />
        <parent link="base_link" />
        <child link="front_castor_link" />
        <axis xyz="0 1 0" />
    </joint>

    <link name="front_castor_link">
        <visual>
            <origin xyz="0 0 0" rpy="1.5707 0 0" />
            <geometry>
                <sphere radius="0.0165" />
            </geometry>
            <material name="black">
                <color rgba="0 0 0 1" />
            </material>
        </visual>
    </link>

    <!-- kinect  -->
    <link name="kinect_link">
        <visual>
            <origin xyz="0 0 0" rpy="0 0 1.5708"/>
            <geometry>
                <mesh filename="package://mbot_description/meshes/kinect.dae" />
            </geometry>
        </visual>
    </link>

    <joint name="kinect_joint" type="fixed">
        <origin xyz="0.08 0 0.038" rpy="0 0 0"/>
        <parent link="base_link"/>
        <child link="kinect_link"/>
    </joint>

</robot>