<?xml version="1.0" ?>
<robot name="mbot">

    <link name="base_link">
        <visual>
            <origin xyz=" 0 0 0" rpy="0 0 0" />
            <geometry>
		 <box size="0.4 0.2 0.16" />	
               
            </geometry>
            <material name="yellow">
                <color rgba="1 0.4 0 0.8"/>
            </material>
        </visual>
    </link>

    <joint name="left_wheel_joint" type="continuous">
        <origin xyz="0 0.2 -0.05" rpy="0 0 0"/>
        <parent link="base_link"/>
        <child link="left_wheel_link"/>
        <axis xyz="0 1 0"/>
    </joint>

    <link name="left_wheel_link">
        <visual>
            <origin xyz="0 0 0" rpy="1.5707 0 0" />
            <geometry>	
                <cylinder radius="0.06" length = "0.025"/>
            </geometry>
            <material name="white">
                <color rgba="1 1 1 0.9"/>
            </material>
        </visual>
    </link>

    <joint name="wheel_joint_axis" type="fixed">
        <origin xyz="0 0 -0.05" rpy="1.5707 0 0"/>
        <parent link="base_link"/>
        <child link="left_wheel_link_axis"/>
        <axis xyz="0 1 0"/>
    </joint>

 <link name="left_wheel_link_axis">
        <visual>
            <origin xyz="0 0 0" rpy="0 0 0" />
            <geometry>
		
                <cylinder radius="0.01" length = "0.4"/>
		 
            </geometry>
            <material name="white">
                <color rgba="1 1 1 0.9"/>
            </material>
        </visual>
    </link>

    <joint name="right_wheel_joint" type="continuous">
        <origin xyz="0 -0.2 -0.05" rpy="0 0 0"/>
        <parent link="base_link"/>
        <child link="right_wheel_link"/>
        <axis xyz="0 1 0"/>
    </joint>

    <link name="right_wheel_link">
        <visual>
            <origin xyz="0 0 0" rpy="1.5707 0 0" />
            <geometry>
                <cylinder radius="0.06" length = "0.025"/>
            </geometry>
            <material name="white">
                <color rgba="1 1 1 0.9"/>
            </material>
        </visual>
    </link>

    <joint name="front_caster_joint" type="continuous">
        <origin xyz="0.18 0 -0.095" rpy="0 0 0"/>
        <parent link="base_link"/>
        <child link="front_caster_link"/>
        <axis xyz="0 1 0"/>
    </joint>

    <link name="front_caster_link">
        <visual>
            <origin xyz="0 0 0" rpy="0 0 0"/>
            <geometry>
                <sphere radius="0.015" />
            </geometry>
            <material name="white">
                <color rgba="1 1 1 0.95"/>
            </material>
        </visual>
    </link>

    <joint name="back_caster_joint" type="continuous">
        <origin xyz="-0.18 0 -0.095" rpy="0 0 0"/>
        <parent link="base_link"/>
        <child link="back_caster_link"/>
        <axis xyz="0 1 0"/>
    </joint>

    <link name="back_caster_link">
        <visual>
            <origin xyz="0 0 0" rpy="0 0 0"/>
            <geometry>
                <sphere radius="0.015" />
            </geometry>
            <material name="white">
                <color rgba="1 1 1 0.95"/>
            </material>
        </visual>
    </link>

    <joint name="kinect_joint" type="fixed">
        <origin xyz="0.15 0 0.08" rpy="0 0 0"/>
        <parent link="base_link"/>
        <child link="kinect_link"/>
    </joint>

    <link name="kinect_link">
        <visual>
            <origin xyz="0 0 0" rpy="0 0 1.5707"/>
            <geometry>
                <mesh filename="package://mbot_description/meshes/MyRGBD.dae" />
            </geometry>
        </visual>
    </link>




    <joint name="laserbase_joint" type="fixed">
        <origin xyz="-0.05 0 0.13" rpy="0 0 0"/>
        <parent link="base_link"/>
        <child link="laserbase_link"/>
    </joint>

    <link name="laserbase_link">
        <visual>
            <origin xyz=" 0 0 0 " rpy="0 0 0" />
            <geometry>
                <box size="0.12 0.2 0.1" />
            </geometry>
            <material name="yellow"/>
        </visual>
    </link>

    <joint name="laser_joint" type="fixed">
        <origin xyz="0 0 0.07" rpy="0 0 0"/>
        <parent link="laserbase_link"/>
        <child link="laser_link"/>
    </joint>

 	<link name="laser_link">
	<visual>
		<origin xyz=" 0 0 0 " rpy="0 0 0" />
		<geometry>
			<cylinder length="0.04" radius="0.05"/>
		</geometry>
		<material name="gray">
			<color rgba="0.2 0.2 0.2 0.95"/>
		</material>
		</visual>
    	</link>
</robot>
